<?xml version='1.0' encoding='utf-8'?>
<mujoco model="T1">
    <compiler angle="radian" meshdir="meshes/" />
    <size njmax="500" nconmax="100" />

    
    <include file="include/t1_header.xml" />
    <include file="include/t1_assets_base.xml" />
    <include file="include/t1_assets_hands.xml" />
    <worldbody>
        <light directional="true" diffuse=".4 .4 .4" specular="0.1 0.1 0.1" pos="0 0 5.0" dir="0 0 -1" castshadow="false" />
        <light directional="true" diffuse=".6 .6 .6" specular="0.2 0.2 0.2" pos="0 0 4" dir="0 0 -1" />
        <geom name="ground" type="plane" pos="0 0 0" size="0 0 1" material="matplane" condim="1" />
        <body name="Trunk" pos="0 0 0.7">
            <inertial pos="0.0551365 -1.42058e-06 0.105062" quat="0.99996 1.40561e-05 -0.00899532 -1.39249e-05" mass="11.7" diaginertia="0.0915404 0.0767787 0.0556055" />
            <site name="imu" size="0.01" pos="0.0 0.0 0.0" />
            <freejoint />
            <geom type="mesh" contype="0" conaffinity="0" group="1" rgba="0.76 0.76 0.76 1.0" mesh="Trunk" />
            <geom size="0.075 0.1 0.15" pos="0.06 0 0.12" type="box" rgba="0.76 0.76 0.76 0.0" />
            <body name="H1" pos="0.0625 0 0.243">
                <inertial pos="-0.000508 -0.001403 0.057432" quat="0.763881 -0.0132172 0.00173419 0.645219" mass="0.44391" diaginertia="0.000241549 0.00022351 0.000149941" />
                <joint name="AAHead_yaw" pos="0 0 0" axis="0 0 1" limited="true" range="-1.57 1.57" />
                <geom type="mesh" contype="0" conaffinity="0" group="1" rgba="0.4 0.4 0.4 1.0" mesh="H1" />
                <body name="H2" pos="0 0 0.06185">
                    <camera name="head_cam" pos="0.08 0 0.12" quat="1 0 0 0" fovy="70" />
                    <inertial pos="0.007802 0.001262 0.098631" quat="0.988453 0.106172 -0.0745686 -0.0782786" mass="0.631019" diaginertia="0.00203553 0.00192467 0.00172381" />
                    <joint name="Head_pitch" pos="0 0 0" axis="0 1 0" limited="true" range="-0.35 1.22" />
                    <geom type="mesh" contype="0" conaffinity="0" group="1" rgba="0.4 0.4 0.4 1.0" mesh="H2" />
                    <geom size="0.08" pos="0.01 0 0.11" rgba="0.4 0.4 0.4 0.0" />
                    <site name="head_anchor_site" pos="0.01 0 0.11" size="0.01" rgba="0.9 0.3 0.3 0.5" />
                </body>
            </body>
            <body name="AL1" pos="0.0575 0.1063 0.219" quat="1 0 0.000440565 0">
                <inertial pos="-0.000677 0.044974 0" quat="0.50423 0.495734 -0.50423 0.495734" mass="0.53" diaginertia="0.001367 0.00129329 0.000292711" />
                <joint name="Left_Shoulder_Pitch" pos="0 0 0" axis="0 1 0" limited="true" range="-3.3469 1.2255" />
                <geom type="mesh" contype="0" conaffinity="0" group="1" rgba="0.76 0.76 0.76 1.0" mesh="AL1" />
                <body name="AL2" pos="0 0.047 0">
                    <inertial pos="0.003862 0.037976 0" quat="0.487991 0.511727 -0.487991 0.511727" mass="0.16" diaginertia="0.000401 0.00034538 0.00017662" />
                    <joint name="Left_Shoulder_Roll" pos="0 0 0" axis="1 0 0" limited="true" range="-1.7239 1.7357" />
                    <geom type="mesh" contype="0" conaffinity="0" group="1" rgba="0.4 0.4 0.4 1.0" mesh="AL2" />
                    <body name="AL3" pos="0.00025 0.0605 0">
                        <inertial pos="0 0.085353 -9.9e-05" quat="0.70641 0.707803 0 0" mass="1.02" diaginertia="0.012869 0.012798 0.000620953" />
                        <joint name="Left_Elbow_Pitch" pos="0 0 0" axis="0 1 0" limited="true" range="-2.3249 2.2581" />
                        <geom type="mesh" contype="0" conaffinity="0" group="1" rgba="0.4 0.4 0.4 1.0" mesh="AL3" />
                        <geom size="0.03 0.075" pos="0 0.05 0" quat="0.707105 0.707108 0 0" type="cylinder" rgba="0.4 0.4 0.4 0.0" />
                        <body name="AL4" pos="0 0.1471 0">
                            <inertial pos="-0.00046851 0.062372 0.0015178" quat="0.708114 0.706086 -0.00272503 -0.00309075" mass="0.2984" diaginertia="0.0016731 0.00160801 0.00021389" />
                            <joint name="Left_Elbow_Yaw" pos="0 0 0" axis="0 0 1" limited="true" range="-2.1418 1.6978" />
                            <geom size="0.04 0.07" pos="0 0.08 0" quat="0.707105 0.707108 0 0" type="cylinder" rgba="0.4 0.4 0.4 0.0" />
                            <geom type="mesh" contype="0" conaffinity="0" group="1" rgba="0.75294 0.75294 0.75294 1" mesh="AL4" />
                            <body name="AL5" pos="0 0.105 0.00025">
                                <inertial pos="-3.8402e-05 0.036076 0.0056711" quat="0.763252 0.646101 0 0" mass="0.42219" diaginertia="0.000823 0.000801406 0.000199594" />
                                <joint name="Left_Wrist_Pitch" pos="0 0 0" axis="0 1 0" limited="true" range="-2.6164 2.6209" />
                                <geom type="mesh" contype="0" conaffinity="0" group="1" rgba="0.75294 0.75294 0.75294 1" mesh="AL5" />
                                <body name="AL6" pos="0 0.042 0">
                                    <inertial pos="-0.00072939 0.056578 -0.0056257" quat="0.701498 0.712537 0.00305334 -0.0134832" mass="0.26532" diaginertia="0.00117124 0.00113821 0.000165544" />
                                    <joint name="Left_Wrist_Yaw" pos="0 0 0" axis="0 0 1" limited="true" range="-1.8610 1.4815" />
                                    <geom type="mesh" contype="0" conaffinity="0" group="1" rgba="0.75294 0.75294 0.75294 1" mesh="AL6" />
                                    <geom size="0.035 0.035" pos="0 0.055 0" quat="0.707105 0.707108 0 0" type="cylinder" rgba="0.4 0.4 0.4 0.0" />
                                    <body name="left_inspire_hand" pos="0.00475 0.07 0.0015">
                                            <inertial pos="-0.00234 0.11633 0.00150" quat="-0.489929 0.485457 0.460832 0.558512" mass="0.62" diaginertia="0.001458 0.001258 0.000479" /><joint name="Left_Hand_Roll" pos="0 0 0" axis="1 0 0" limited="true" range="-1.0348 1.6066" />
                                        
                                        <geom size="0.042 0.075" pos="-0.00476 0.13133 -0.00244" quat="0.707105 -0.707108 0 0" type="cylinder" rgba="0.4 0.4 0.4 0.0" /><geom pos="-0.00476 0.03133 -0.00244" quat="0.707105 -0.707108 0 0" type="mesh" contype="0" conaffinity="0" group="1" rgba="1 1 1 1" mesh="left_hand_base_link" />
                                            <geom pos="-0.00440 0.04363 -0.00244" quat="0.707105 -0.707108 0 0" type="mesh" contype="0" conaffinity="0" group="1" rgba="0.411765 0.411765 0.411765 1" mesh="left_hand_palm_force_sensor" />
                                            
                                            <body name="left_thumb_1" pos="0.022139 0.100228 -0.023447" quat="0.707105 -0.707108 0 0">
                                                <inertial pos="0.001442 0.000479 0.002441" quat="1 0 0 0" mass="0.001" diaginertia="1e-9 1e-9 1e-9" />
                                                <joint name="left_thumb_1_joint" pos="0 0 0" axis="0 0 1" range="0 1.1641" />
                                                <geom type="mesh" contype="0" conaffinity="0" group="1" rgba="1 1 1 1" mesh="left_hand_thumb_1" />
                                                <body name="left_thumb_2" pos="0.0073431 0.011232 0.0052" quat="0.0922934 0.0922938 -0.701059 -0.701056">
                                                    <inertial pos="-0.013782 0.013000 -0.008917" quat="1 0 0 0" mass="0.001" diaginertia="1e-9 1e-9 1e-9" />
                                                    <joint name="left_thumb_2_joint" pos="0 0 0" axis="0 0 -1" range="0 0.5864" />
                                                    <geom type="mesh" contype="0" conaffinity="0" group="1" rgba="1 1 1 1" mesh="left_hand_thumb_2" />
                                                    <geom pos="-0.0087121 0.026305 -0.0089605" quat="0.579842 -0.404703 0.579842 0.4047" type="mesh" contype="0" conaffinity="0" group="1" rgba="0.411765 0.411765 0.411765 1" mesh="left_hand_thumb_force_sensor_1" />
                                                    <body name="left_thumb_3" pos="-0.031403 0.021069 -0.001299">
                                                        <inertial pos="-0.011820 0.003532 -0.007650" quat="1 0 0 0" mass="0.001" diaginertia="1e-9 1e-9 1e-9" />
                                                        <joint name="left_thumb_3_joint" pos="0 0 0" axis="0 0 -1" range="0 0.5" />
                                                        <geom type="mesh" contype="0" conaffinity="0" group="1" rgba="1 1 1 1" mesh="left_hand_thumb_3" />
                                                        <geom pos="-0.011771 0.01699 -0.0077514" quat="-0.562601 0.428173 -0.562767 -0.4283" type="mesh" contype="0" conaffinity="0" group="1" rgba="0.411765 0.411765 0.411765 1" mesh="left_hand_thumb_force_sensor_2" />
                                                        <body name="left_thumb_4" pos="-0.0219027 0.0128161 -0.0003">
                                                            <inertial pos="-0.013189 0.004505 -0.007325" quat="1 0 0 0" mass="0.001" diaginertia="1e-9 1e-9 1e-9" />
                                                            <joint name="left_thumb_4_joint" pos="0 0 0" axis="0 0 -1" range="0 3.14" />
                                                            <geom type="mesh" contype="0" conaffinity="0" group="1" rgba="1 1 1 1" mesh="left_hand_thumb_4" />
                                                            <geom pos="-0.014598 0.014721 -0.0073103" quat="0.615305 -0.348423 0.615308 0.348422" type="mesh" contype="0" conaffinity="0" group="1" rgba="0.411765 0.411765 0.411765 1" mesh="left_hand_thumb_force_sensor_3" />
                                                            <geom pos="-0.028987 0.017301 -0.0073513" quat="0.609651 -0.358229 -0.609648 -0.358228" type="mesh" contype="0" conaffinity="0" group="1" rgba="0.411765 0.411765 0.411765 1" mesh="left_hand_thumb_force_sensor_4" />
                                                            <site name="left_thumb_site" pos="-0.028987 0.017301 -0.0073513" size="0.003" rgba="0 1 0 1" />
                                                        </body>
                                                    </body>
                                                </body>
                                            </body>
                                            
                                            <body name="left_index_1" pos="0.033918 0.187728 -0.003002" quat="0.706998 0.012338 0.707000 -0.012341">
                                                <inertial pos="0.001546 0.011970 -0.006650" quat="1 0 0 0" mass="0.001" diaginertia="1e-9 1e-9 1e-9" />
                                                <joint name="left_index_1_joint" pos="0 0 0" axis="0 0 -1" range="0 1.4381" />
                                                <geom type="mesh" contype="0" conaffinity="0" group="1" rgba="1 1 1 1" mesh="left_hand_index_1" />
                                                <geom pos="0.012046 0.019649 -0.006651" quat="0.704358 -0.0873853 0.701686 0.0622873" type="mesh" contype="0" conaffinity="0" group="1" rgba="0.411765 0.411765 0.411765 1" mesh="left_hand_index_force_sensor_1" />
                                                <body name="left_index_2" pos="0.0034259 0.032596 -0.00055">
                                                    <inertial pos="-0.000265 0.022812 -0.006091" quat="1 0 0 0" mass="0.001" diaginertia="1e-9 1e-9 1e-9" />
                                                    <joint name="left_index_2_joint" pos="0 0 0" axis="0 0 -1" range="0 3.14" />
                                                    <geom type="mesh" contype="0" conaffinity="0" group="1" rgba="1 1 1 1" mesh="left_hand_index_2" />
                                                    <geom pos="0.0081655 0.037446 -0.0060795" quat="0.693985 0.109758 0.698536 -0.13559" type="mesh" contype="0" conaffinity="0" group="1" rgba="0.411765 0.411765 0.411765 1" mesh="left_hand_index_force_sensor_2" />
                                                    <geom pos="0.0086237 0.052572 -0.0060954" quat="0.66977 -0.257027 0.658739 0.226735" type="mesh" contype="0" conaffinity="0" group="1" rgba="0.411765 0.411765 0.411765 1" mesh="left_hand_index_force_sensor_3" />
                                                    <site name="left_index_site" pos="0.0086237 0.052572 -0.0060954" size="0.003" rgba="0 1 0 1" />
                                                </body>
                                            </body>
                                            
                                            <body name="left_middle_1" pos="0.012339 0.188328 -0.003002" quat="0.707105 0 0.707108 0">
                                                <inertial pos="0.001546 0.011970 -0.006650" quat="1 0 0 0" mass="0.001" diaginertia="1e-9 1e-9 1e-9" />
                                                <joint name="left_middle_1_joint" pos="0 0 0" axis="0 0 -1" range="0 1.4381" />
                                                <geom type="mesh" contype="0" conaffinity="0" group="1" rgba="1 1 1 1" mesh="left_hand_middle_1" />
                                                <geom pos="0.012046 0.019649 -0.006651" quat="0.703135 -0.0748472 0.703133 0.0748492" type="mesh" contype="0" conaffinity="0" group="1" rgba="0.411765 0.411765 0.411765 1" mesh="left_hand_middle_force_sensor_1" />
                                                <body name="left_middle_2" pos="0.0034259 0.032596 -0.00055">
                                                    <inertial pos="0.000349 0.024743 -0.006100" quat="1 0 0 0" mass="0.001" diaginertia="1e-9 1e-9 1e-9" />
                                                    <joint name="left_middle_2_joint" pos="0 0 0" axis="0 0 -1" range="0 3.14" />
                                                    <geom type="mesh" contype="0" conaffinity="0" group="1" rgba="1 1 1 1" mesh="left_hand_middle_2" />
                                                    <geom pos="0.009086 0.040962 -0.0061003" quat="0.694859 0.131043 0.694857 -0.131042" type="mesh" contype="0" conaffinity="0" group="1" rgba="0.411765 0.411765 0.411765 1" mesh="left_hand_middle_force_sensor_2" />
                                                    <geom pos="0.00982886 0.0560509 -0.00610028" quat="0.667287 -0.233944 0.667285 0.233943" type="mesh" contype="0" conaffinity="0" group="1" rgba="0.411765 0.411765 0.411765 1" mesh="left_hand_middle_force_sensor_3" />
                                                    <site name="left_middle_site" pos="0.00982886 0.0560509 -0.00610028" size="0.003" rgba="0 1 0 1" />
                                                </body>
                                            </body>
                                            
                                            <body name="left_ring_1" pos="-0.009291 0.188158 -0.003002" quat="0.706863 -0.018524 0.706865 0.018522">
                                                <inertial pos="0.001546 0.011970 -0.006650" quat="1 0 0 0" mass="0.001" diaginertia="1e-9 1e-9 1e-9" />
                                                <joint name="left_ring_1_joint" pos="0 0 0" axis="0 0 -1" range="0 1.4381" />
                                                <geom type="mesh" contype="0" conaffinity="0" group="1" rgba="1 1 1 1" mesh="left_hand_ring_1" />
                                                <geom pos="0.012046 0.019649 -0.006651" quat="0.700876 -0.0559809 0.704887 0.0936618" type="mesh" contype="0" conaffinity="0" group="1" rgba="0.411765 0.411765 0.411765 1" mesh="left_hand_ring_force_sensor_1" />
                                                <body name="left_ring_2" pos="0.0034259 0.032596 -0.00055">
                                                    <inertial pos="-0.000265 0.022812 -0.006091" quat="1 0 0 0" mass="0.001" diaginertia="1e-9 1e-9 1e-9" />
                                                    <joint name="left_ring_2_joint" pos="0 0 0" axis="0 0 -1" range="0 3.14" />
                                                    <geom type="mesh" contype="0" conaffinity="0" group="1" rgba="1 1 1 1" mesh="left_hand_ring_2" />
                                                    <geom pos="0.0081655 0.037446 -0.0060795" quat="0.699527 0.142038 0.692694 -0.103257" type="mesh" contype="0" conaffinity="0" group="1" rgba="0.411765 0.411765 0.411765 1" mesh="left_hand_ring_force_sensor_2" />
                                                    <geom pos="0.0086202 -0.01538 -0.028643" quat="0.69691 -0.0553604 0.708832 0.0938534" type="mesh" contype="0" conaffinity="0" group="1" rgba="0.411765 0.411765 0.411765 1" mesh="left_hand_ring_force_sensor_3" />
                                                    <site name="left_ring_site" pos="0.0086237 0.052572 -0.0060954" size="0.003" rgba="0 1 0 1" />
                                                </body>
                                            </body>
                                            
                                            <body name="left_little_1" pos="-0.030677 0.184978 -0.003002" quat="0.706137 -0.037000 0.706140 0.036998">
                                                <inertial pos="0.001546 0.011970 -0.006650" quat="1 0 0 0" mass="0.001" diaginertia="1e-9 1e-9 1e-9" />
                                                <joint name="left_little_1_joint" pos="0 0 0" axis="0 0 -1" range="0 1.4381" />
                                                <geom type="mesh" contype="0" conaffinity="0" group="1" rgba="1 1 1 1" mesh="left_hand_little_1" />
                                                <geom pos="0.0098773 0.060279 -0.0066672" quat="0.702403 0.158793 0.689047 -0.0814204" type="mesh" contype="0" conaffinity="0" group="1" rgba="0.411765 0.411765 0.411765 1" mesh="left_hand_little_force_sensor_1" />
                                                <body name="left_little_2" pos="0.0034259 0.032596 -0.00055">
                                                    <inertial pos="-0.001058 0.017982 -0.006101" quat="1 0 0 0" mass="0.001" diaginertia="1e-9 1e-9 1e-9" />
                                                    <joint name="left_little_2_joint" pos="0 0 0" axis="0 0 -1" range="0 3.14" />
                                                    <geom type="mesh" contype="0" conaffinity="0" group="1" rgba="1 1 1 1" mesh="left_hand_little_2" />
                                                    <geom pos="0.0086237 0.053732 0.019972" quat="0.661298 -0.20185 0.665159 0.281968" type="mesh" contype="0" conaffinity="0" group="1" rgba="0.411765 0.411765 0.411765 1" mesh="left_hand_little_force_sensor_2" />
                                                    <geom pos="0.0063973 0.042707 -0.0061154" quat="0.645291 -0.198165 0.678772 0.289136" type="mesh" contype="0" conaffinity="0" group="1" rgba="0.411765 0.411765 0.411765 1" mesh="left_hand_little_force_sensor_3" />
                                                    <site name="left_little_site" pos="0.0063973 0.042707 -0.0061154" size="0.003" rgba="0 1 0 1" />
                                                </body>
                                            </body>
                                            
                                        </body>
                                    </body>
                            </body>
                        </body>
                    </body>
                </body>
            </body>
            <body name="AR1" pos="0.0575 -0.1063 0.219" quat="1 0 0.000440565 0">
                <inertial pos="-0.000677 -0.044974 0" quat="0.50423 0.495734 -0.50423 0.495734" mass="0.53" diaginertia="0.001367 0.00129329 0.000292711" />
                <joint name="Right_Shoulder_Pitch" pos="0 0 0" axis="0 1 0" limited="true" range="-3.3953 1.1954" />
                <geom type="mesh" contype="0" conaffinity="0" group="1" rgba="0.76 0.76 0.76 1.0" mesh="AR1" />
                <body name="AR2" pos="0 -0.047 0">
                    <inertial pos="0.003862 -0.037976 0" quat="0.511727 0.487991 -0.511727 0.487991" mass="0.16" diaginertia="0.000401 0.00034538 0.00017662" />
                    <joint name="Right_Shoulder_Roll" pos="0 0 0" axis="1 0 0" limited="true" range="-1.6190 1.7392" />
                    <geom type="mesh" contype="0" conaffinity="0" group="1" rgba="0.4 0.4 0.4 1.0" mesh="AR2" />
                    <body name="AR3" pos="0.00025 -0.0605 0">
                        <inertial pos="0 -0.085353 -9.9e-05" quat="0.707803 0.70641 0 0" mass="1.02" diaginertia="0.012869 0.012798 0.000620953" />
                        <joint name="Right_Elbow_Pitch" pos="0 0 0" axis="0 1 0" limited="true" range="-2.3154 2.2749" />
                        <geom type="mesh" contype="0" conaffinity="0" group="1" rgba="0.4 0.4 0.4 1.0" mesh="AR3" />
                        <geom size="0.03 0.075" pos="0 -0.05 0" quat="0.707105 0.707108 0 0" type="cylinder" rgba="0.4 0.4 0.4 0.0" />
                        <body name="AR4" pos="0 -0.1471 0">
                            <inertial pos="-0.0004573 -0.067734 0.0017465" quat="0.706214 0.70799 0.00258227 0.0022281" mass="0.3599" diaginertia="0.0022921 0.00222301 0.000233892" />
                            <joint name="Right_Elbow_Yaw" pos="0 0 0" axis="0 0 1" limited="true" range="-1.6917 2.1578" />
                            <geom size="0.04 0.07" pos="0 -0.08 0" quat="0.707105 0.707108 0 0" type="cylinder" rgba="0.4 0.4 0.4 0.0" />
                            <geom type="mesh" contype="0" conaffinity="0" group="1" rgba="0.75294 0.75294 0.75294 1" mesh="AR4" />
                            <body name="AR5" pos="0 -0.105 0.00025">
                                <inertial pos="3.7355e-05 -0.035638 0.0053147" quat="0.648697 0.761046 0 0" mass="0.43402" diaginertia="0.000836 0.000812239 0.000204761" />
                                <joint name="Right_Wrist_Pitch" pos="0 0 0" axis="0 1 0" limited="true" range="-2.6133 2.6270" />
                                <geom type="mesh" contype="0" conaffinity="0" group="1" rgba="0.75294 0.75294 0.75294 1" mesh="AR5" />
                                <body name="AR6" pos="0 -0.042 0">
                                    <inertial pos="-0.0011437 -0.056205 -0.0056621" quat="0.711908 0.702081 0.0164127 -0.000464544" mass="0.28215" diaginertia="0.00123856 0.00121017 0.000181264" />
                                    <joint name="Right_Wrist_Yaw" pos="0 0 0" axis="0 0 1" limited="true" range="-1.4502 1.8935" />
                                    <geom type="mesh" contype="0" conaffinity="0" group="1" rgba="0.75294 0.75294 0.75294 1" mesh="AR6" />
                                    <geom size="0.035 0.035" pos="0 -0.055 0" quat="0.707105 0.707108 0 0" type="cylinder" rgba="0.4 0.4 0.4 0.0" />
                                    <body name="right_inspire_hand" pos="0.00475 -0.07 0.0015">
                                            <inertial pos="-0.00601 -0.12189 0.00167" quat="0.543049 0.465191 0.467320 -0.519911" mass="0.62" diaginertia="0.001217 0.001034 0.000419" /><joint name="Right_Hand_Roll" pos="0 0 0" axis="1 0 0" limited="true" range="-1.6768 0.9993" />
                                        
                                        <geom size="0.042 0.075" pos="-0.00676 -0.13507 -0.00244" quat="0 0 -0.707108 0.707105" type="cylinder" rgba="0.4 0.4 0.4 0.0" /><geom pos="-0.00676 -0.03507 -0.00244" quat="0 0 -0.707108 0.707105" type="mesh" contype="0" conaffinity="0" group="1" rgba="1 1 1 1" mesh="right_hand_base_link" />
                                            <geom pos="-0.00640 -0.04737 -0.00244" quat="0 0 -0.707108 0.707105" type="mesh" contype="0" conaffinity="0" group="1" rgba="0.411765 0.411765 0.411765 1" mesh="right_hand_palm_force_sensor" />
                                            
                                            <body name="right_thumb_1" pos="0.020139 -0.103969 -0.023447" quat="0.000001 -0.000001 -0.707108 0.707105">
                                                <inertial pos="-0.001442 0.000479 0.002441" quat="1 0 0 0" mass="0.001" diaginertia="1e-9 1e-9 1e-9" />
                                                <joint name="right_thumb_1_joint" pos="0 0 0" axis="0 0 -1" range="0 1.1641" />
                                                <geom type="mesh" contype="0" conaffinity="0" group="1" rgba="1 1 1 1" mesh="right_hand_thumb_1" />
                                                <body name="right_thumb_2" pos="-0.0079252 0.0090599 0.0052" quat="0.0922934 0.0922938 0.701059 0.701056">
                                                    <inertial pos="0.013782 0.012999 -0.006669" quat="1 0 0 0" mass="0.001" diaginertia="1e-9 1e-9 1e-9" />
                                                    <joint name="right_thumb_2_joint" pos="0 0 0" axis="0 0 1" range="0 0.5864" />
                                                    <geom type="mesh" contype="0" conaffinity="0" group="1" rgba="1 1 1 1" mesh="right_hand_thumb_2" />
                                                    <geom pos="0.0087121 0.026305 -0.0067115" quat="0.579327 -0.405437 -0.579328 -0.405439" type="mesh" contype="0" conaffinity="0" group="1" rgba="0.411765 0.411765 0.411765 1" mesh="right_hand_thumb_force_sensor_1" />
                                                    <body name="right_thumb_3" pos="0.031403 0.021069 0.00095">
                                                        <inertial pos="0.011820 0.003532 -0.007650" quat="1 0 0 0" mass="0.001" diaginertia="1e-9 1e-9 1e-9" />
                                                        <joint name="right_thumb_3_joint" pos="0 0 0" axis="0 0 1" range="0 0.5" />
                                                        <geom type="mesh" contype="0" conaffinity="0" group="1" rgba="1 1 1 1" mesh="right_hand_thumb_3" />
                                                        <geom pos="0.011771 0.01699 -0.0077514" quat="-0.562601 0.428173 0.562767 0.4283" type="mesh" contype="0" conaffinity="0" group="1" rgba="0.411765 0.411765 0.411765 1" mesh="right_hand_thumb_force_sensor_2" />
                                                        <body name="right_thumb_4" pos="0.021903 0.012816 -0.0003">
                                                            <inertial pos="0.013189 0.004504 -0.007325" quat="1 0 0 0" mass="0.001" diaginertia="1e-9 1e-9 1e-9" />
                                                            <joint name="right_thumb_4_joint" pos="0 0 0" axis="0 0 1" range="0 3.14" />
                                                            <geom type="mesh" contype="0" conaffinity="0" group="1" rgba="1 1 1 1" mesh="right_hand_thumb_4" />
                                                            <geom pos="0.014598 0.01472 -0.0073103" quat="0.615658 -0.347798 -0.615661 -0.347797" type="mesh" contype="0" conaffinity="0" group="1" rgba="0.411765 0.411765 0.411765 1" mesh="right_hand_thumb_force_sensor_3" />
                                                            <geom pos="0.028987 0.017301 -0.0073512" quat="0.609148 -0.359083 0.609147 0.359081" type="mesh" contype="0" conaffinity="0" group="1" rgba="0.411765 0.411765 0.411765 1" mesh="right_hand_thumb_force_sensor_4" />
                                                            <site name="right_thumb_site" pos="0.028987 0.017301 -0.0073512" size="0.003" rgba="0 1 0 1" />
                                                        </body>
                                                    </body>
                                                </body>
                                            </body>
                                            
                                            <body name="right_index_1" pos="0.031918 -0.191469 -0.003002" quat="0.012340 -0.707000 -0.012337 -0.706998">
                                                <inertial pos="-0.001546 0.011970 -0.006650" quat="1 0 0 0" mass="0.001" diaginertia="1e-9 1e-9 1e-9" />
                                                <joint name="right_index_1_joint" pos="0 0 0" axis="0 0 1" range="0 1.4381" />
                                                <geom type="mesh" contype="0" conaffinity="0" group="1" rgba="1 1 1 1" mesh="right_hand_index_1" />
                                                <geom pos="-0.012046 0.019649 -0.006651" quat="0.704358 -0.0873853 -0.701686 -0.0622873" type="mesh" contype="0" conaffinity="0" group="1" rgba="0.411765 0.411765 0.411765 1" mesh="right_hand_index_force_sensor_1" />
                                                <body name="right_index_2" pos="-0.0034259 0.032596 -0.00055">
                                                    <inertial pos="0.000265 0.022812 -0.006091" quat="1 0 0 0" mass="0.001" diaginertia="1e-9 1e-9 1e-9" />
                                                    <joint name="right_index_2_joint" pos="0 0 0" axis="0 0 1" range="0 3.14" />
                                                    <geom type="mesh" contype="0" conaffinity="0" group="1" rgba="1 1 1 1" mesh="right_hand_index_2" />
                                                    <geom pos="-0.0081655 0.037446 -0.0060795" quat="0.693985 0.109758 -0.698536 0.13559" type="mesh" contype="0" conaffinity="0" group="1" rgba="0.411765 0.411765 0.411765 1" mesh="right_hand_index_force_sensor_2" />
                                                    <geom pos="-0.0086237 0.052572 -0.0060954" quat="0.66977 -0.257027 -0.658739 -0.226735" type="mesh" contype="0" conaffinity="0" group="1" rgba="0.411765 0.411765 0.411765 1" mesh="right_hand_index_force_sensor_3" />
                                                    <site name="right_index_site" pos="-0.00862373 0.0525719 -0.00609539" size="0.003" rgba="0 1 0 1" />
                                                </body>
                                            </body>
                                            
                                            <body name="right_middle_1" pos="0.010339 -0.192069 -0.003002" quat="0.000002 -0.707108 0.000001 -0.707105">
                                                <inertial pos="-0.001546 0.011970 -0.006650" quat="1 0 0 0" mass="0.001" diaginertia="1e-9 1e-9 1e-9" />
                                                <joint name="right_middle_1_joint" pos="0 0 0" axis="0 0 1" range="0 1.4381" />
                                                <geom type="mesh" contype="0" conaffinity="0" group="1" rgba="1 1 1 1" mesh="right_hand_middle_1" />
                                                <geom pos="-0.012046 0.019649 -0.006651" quat="-0.703076 0.0754056 0.703073 0.0754054" type="mesh" contype="0" conaffinity="0" group="1" rgba="0.411765 0.411765 0.411765 1" mesh="right_hand_middle_force_sensor_1" />
                                                <body name="right_middle_2" pos="-0.0034259 0.032596 -0.00055">
                                                    <inertial pos="-0.000348 0.024743 -0.006101" quat="1 0 0 0" mass="0.001" diaginertia="1e-9 1e-9 1e-9" />
                                                    <joint name="right_middle_2_joint" pos="0 0 0" axis="0 0 1" range="0 3.14" />
                                                    <geom type="mesh" contype="0" conaffinity="0" group="1" rgba="1 1 1 1" mesh="right_hand_middle_2" />
                                                    <geom pos="-0.0090859 0.040963 -0.0061003" quat="-0.695008 -0.130248 0.695006 -0.130249" type="mesh" contype="0" conaffinity="0" group="1" rgba="0.411765 0.411765 0.411765 1" mesh="right_hand_middle_force_sensor_2" />
                                                    <geom pos="-0.0098294 0.056051 -0.0061006" quat="-0.667101 0.234473 0.667099 0.234472" type="mesh" contype="0" conaffinity="0" group="1" rgba="0.411765 0.411765 0.411765 1" mesh="right_hand_middle_force_sensor_3" />
                                                    <site name="right_middle_site" pos="-0.0098294 0.056051 -0.0061006" size="0.003" rgba="0 1 0 1" />
                                                </body>
                                            </body>
                                            
                                            <body name="right_ring_1" pos="-0.011292 -0.191899 -0.003002" quat="-0.018523 -0.706865 0.018525 -0.706863">
                                                <inertial pos="-0.001546 0.011970 -0.006650" quat="1 0 0 0" mass="0.001" diaginertia="1e-9 1e-9 1e-9" />
                                                <joint name="right_ring_1_joint" pos="0 0 0" axis="0 0 1" range="0 1.4381" />
                                                <geom type="mesh" contype="0" conaffinity="0" group="1" rgba="1 1 1 1" mesh="right_hand_ring_1" />
                                                <geom pos="-0.0120462 0.0196485 -0.00665098" quat="0.700879 -0.0559904 -0.704887 -0.0936441" type="mesh" contype="0" conaffinity="0" group="1" rgba="0.411765 0.411765 0.411765 1" mesh="right_hand_ring_force_sensor_1" />
                                                <body name="right_ring_2" pos="-0.0034259 0.032596 -0.00055">
                                                    <inertial pos="0.000265 0.022812 -0.006091" quat="1 0 0 0" mass="0.001" diaginertia="1e-9 1e-9 1e-9" />
                                                    <joint name="right_ring_2_joint" pos="0 0 0" axis="0 0 1" range="0 3.14" />
                                                    <geom type="mesh" contype="0" conaffinity="0" group="1" rgba="1 1 1 1" mesh="right_hand_ring_2" />
                                                    <geom pos="-0.00816549 0.0374458 -0.00607949" quat="0.699529 0.14203 -0.692696 0.103242" type="mesh" contype="0" conaffinity="0" group="1" rgba="0.411765 0.411765 0.411765 1" mesh="right_hand_ring_force_sensor_2" />
                                                    <geom pos="-0.00862373 0.0525719 -0.00609539" quat="0.655775 -0.219109 -0.672303 -0.264497" type="mesh" contype="0" conaffinity="0" group="1" rgba="0.411765 0.411765 0.411765 1" mesh="right_hand_ring_force_sensor_3" />
                                                    <site name="right_ring_site" pos="-0.00862373 0.0525719 -0.00609539" size="0.003" rgba="0 1 0 1" />
                                                </body>
                                            </body>
                                            
                                            <body name="right_little_1" pos="-0.032677 -0.188719 -0.003002" quat="-0.036999 -0.706139 0.037001 -0.706137">
                                                <inertial pos="-0.001546 0.011970 -0.006650" quat="1 0 0 0" mass="0.001" diaginertia="1e-9 1e-9 1e-9" />
                                                <joint name="right_little_1_joint" pos="0 0 0" axis="0 0 1" range="0 1.4381" />
                                                <geom type="mesh" contype="0" conaffinity="0" group="1" rgba="1 1 1 1" mesh="right_hand_little_1" />
                                                <geom pos="-0.0120462 0.0196485 -0.00665098" quat="0.698121 -0.0371013 -0.706133 -0.112372" type="mesh" contype="0" conaffinity="0" group="1" rgba="0.411765 0.411765 0.411765 1" mesh="right_hand_little_force_sensor_1" />
                                                <body name="right_little_2" pos="-0.0034259 0.032596 -0.00055">
                                                    <inertial pos="0.001058 0.017982 -0.006101" quat="1 0 0 0" mass="0.001" diaginertia="1e-9 1e-9 1e-9" />
                                                    <joint name="right_little_2_joint" pos="0 0 0" axis="0 0 1" range="0 3.14" />
                                                    <geom type="mesh" contype="0" conaffinity="0" group="1" rgba="1 1 1 1" mesh="right_hand_little_2" />
                                                    <geom pos="-0.00645124 0.0276833 -0.00611719" quat="0.702403 0.158797 -0.689045 0.0814212" type="mesh" contype="0" conaffinity="0" group="1" rgba="0.411765 0.411765 0.411765 1" mesh="right_hand_little_force_sensor_2" />
                                                    <geom pos="-0.00639723 0.0427069 -0.00611537" quat="0.645296 -0.19817 -0.67877 -0.289124" type="mesh" contype="0" conaffinity="0" group="1" rgba="0.411765 0.411765 0.411765 1" mesh="right_hand_little_force_sensor_3" />
                                                    <site name="right_little_site" pos="-0.00639723 0.0427069 -0.00611537" size="0.003" rgba="0 1 0 1" />
                                                </body>
                                            </body>
                                            
                                        </body>
                                    </body>
                            </body>
                        </body>
                    </body>
                </body>
            </body>
            <body name="Waist" pos="0.0625 0 -0.1155">
                <inertial pos="0.002284 3e-06 0.007301" quat="0.983649 0.000360386 -0.180076 0.00269791" mass="2.581" diaginertia="0.00536742 0.005299 0.00474258" />
                <joint name="Waist" pos="0 0 0" axis="0 0 1" limited="true" range="-1.047 1.047" />
                <geom type="mesh" contype="0" conaffinity="0" group="1" rgba="0.4 0.4 0.4 1.0" mesh="Waist" />
                <body name="Hip_Pitch_Left" pos="0 0.106 0">
                    <inertial pos="0.000534 -0.007296 -0.018083" quat="0.975141 0.2211 0.0145808 0.0017406" mass="1.021" diaginertia="0.00180547 0.00145926 0.00125327" />
                    <joint name="Left_Hip_Pitch" pos="0 0 0" axis="0 1 0" limited="true" range="-1.8 1.57" />
                    <geom type="mesh" contype="0" conaffinity="0" group="1" rgba="0.76 0.76 0.76 1.0" mesh="Hip_Pitch_Left" />
                    <body name="Hip_Roll_Left" pos="0 0 -0.02">
                        <inertial pos="0.001101 2.4e-05 -0.05375" quat="0.707081 -0.00599604 -0.00599604 0.707081" mass="0.385" diaginertia="0.001743 0.00151729 0.000514712" />
                        <joint name="Left_Hip_Roll" pos="0 0 0" axis="1 0 0" limited="true" range="-0.3 1.57" />
                        <geom type="mesh" contype="0" conaffinity="0" group="1" rgba="0.4 0.4 0.4 1.0" mesh="Hip_Roll_Left" />
                        <geom size="0.05 0.08" pos="0 0 -0.08" type="cylinder" rgba="0.4 0.4 0.4 0.0" />
                        <body name="Hip_Yaw_Left" pos="0 0 -0.081854">
                            <inertial pos="-0.007233 0.000206 -0.089184" quat="0.696808 -0.033953 -0.0315708 0.715758" mass="2.166" diaginertia="0.0257334 0.0253024 0.00259215" />
                            <joint name="Left_Hip_Yaw" pos="0 0 0" axis="0 0 1" limited="true" range="-1 1" />
                            <geom type="mesh" contype="0" conaffinity="0" group="1" rgba="0.4 0.4 0.4 1.0" mesh="Hip_Yaw_Left" />
                            <geom size="0.05 0.04" pos="-0.015 0 -0.135" quat="0.707141 0.707073 0 0" type="cylinder" rgba="0.4 0.4 0.4 0.0" />
                            <body name="Shank_Left" pos="-0.014 0 -0.134">
                                <inertial pos="-0.006012 0.000259 -0.124318" quat="0.997573 0.00144024 -0.023949 0.0653706" mass="1.73" diaginertia="0.0346951 0.0345375 0.00185844" />
                                <joint name="Left_Knee_Pitch" pos="0 0 0" axis="0 1 0" limited="true" range="0 2.34" />
                                <geom type="mesh" contype="0" conaffinity="0" group="1" rgba="0.4 0.4 0.4 1.0" mesh="Shank_Left" />
                                <geom size="0.05 0.04 0.05" pos="0 0 -0.13" type="box" rgba="0.4 0.4 0.4 0.0" />
                                <body name="Ankle_Cross_Left" pos="0 0 -0.28">
                                    <inertial pos="-0.003722 0 -0.007981" quat="0.443136 0.551027 0.551027 0.443136" mass="0.073" diaginertia="2.9e-05 2.56589e-05 1.13411e-05" />
                                    <joint name="Left_Ankle_Pitch" pos="0 0 0" axis="0 1 0" limited="true" range="-0.87 0.35" />
                                    <geom type="mesh" contype="0" conaffinity="0" group="1" rgba="0.4 0.4 0.4 1.0" mesh="Ankle_Cross_Left" />
                                    <body name="left_foot_link" pos="0 0.00025 -0.012">
                                        <inertial pos="-0.000249 0 -0.00914" quat="0 0.599183 0 0.800612" mass="0.685" diaginertia="0.0027142 0.002385 0.0021708" />
                                        <joint name="Left_Ankle_Roll" pos="0 0 0" axis="1 0 0" limited="true" range="-0.44 0.44" />
                                        <geom type="mesh" contype="0" conaffinity="0" group="1" rgba="0.4 0.4 0.4 1.0" mesh="left_foot_link" />
                                        <geom size="0.1115 0.05 0.015" pos="0.01 0 -0.015" type="box" rgba="0.4 0.4 0.4 0.0" />
                                        <site name="left_foot" pos="0.05 0 -0.025" size="0.01" rgba="0.2 0.8 0.2 0.8" />
                                    </body>
                                </body>
                            </body>
                        </body>
                    </body>
                </body>
                <body name="Hip_Pitch_Right" pos="0 -0.106 0">
                    <inertial pos="0.000534 0.007514 -0.018082" quat="0.973446 -0.228403 0.0147148 -0.00419349" mass="1.021" diaginertia="0.00180552 0.0014632 0.00124928" />
                    <joint name="Right_Hip_Pitch" pos="0 0 0" axis="0 1 0" limited="true" range="-1.8 1.57" />
                    <geom type="mesh" contype="0" conaffinity="0" group="1" rgba="0.76 0.76 0.76 1.0" mesh="Hip_Pitch_Right" />
                    <body name="Hip_Roll_Right" pos="0 0 -0.02">
                        <inertial pos="0.001099 2.4e-05 -0.053748" quat="0.707081 -0.00599604 -0.00599604 0.707081" mass="0.385" diaginertia="0.001743 0.00151729 0.000514712" />
                        <joint name="Right_Hip_Roll" pos="0 0 0" axis="1 0 0" limited="true" range="-1.57 0.3" />
                        <geom type="mesh" contype="0" conaffinity="0" group="1" rgba="0.4 0.4 0.4 1.0" mesh="Hip_Roll_Right" />
                        <geom size="0.05 0.08" pos="0 0 -0.08" type="cylinder" rgba="0.4 0.4 0.4 0.0" />
                        <body name="Hip_Yaw_Right" pos="0 0 -0.081854">
                            <inertial pos="-0.007191 -0.000149 -0.08922" quat="0.714468 -0.0315638 -0.0336391 0.698146" mass="2.17" diaginertia="0.0257623 0.0253298 0.00259389" />
                            <joint name="Right_Hip_Yaw" pos="0 0 0" axis="0 0 1" limited="true" range="-1 1" />
                            <geom type="mesh" contype="0" conaffinity="0" group="1" rgba="0.4 0.4 0.4 1.0" mesh="Hip_Yaw_Right" />
                            <geom size="0.05 0.04" pos="-0.015 0 -0.135" quat="0.707141 0.707073 0 0" type="cylinder" rgba="0.4 0.4 0.4 0.0" />
                            <body name="Shank_Right" pos="-0.014 0 -0.134">
                                <inertial pos="-0.005741 -0.000541 -0.122602" quat="0.99926 -0.000580963 -0.023461 -0.0304754" mass="1.79" diaginertia="0.0351717 0.0349574 0.00196589" />
                                <joint name="Right_Knee_Pitch" pos="0 0 0" axis="0 1 0" limited="true" range="0 2.34" />
                                <geom type="mesh" contype="0" conaffinity="0" group="1" rgba="0.4 0.4 0.4 1.0" mesh="Shank_Right" />
                                <geom size="0.05 0.04 0.05" pos="0 0 -0.13" type="box" rgba="0.4 0.4 0.4 0.0" />
                                <body name="Ankle_Cross_Right" pos="0 0 -0.28">
                                    <inertial pos="-0.003722 0 -0.007981" quat="0.443136 0.551027 0.551027 0.443136" mass="0.073" diaginertia="2.9e-05 2.56589e-05 1.13411e-05" />
                                    <joint name="Right_Ankle_Pitch" pos="0 0 0" axis="0 1 0" limited="true" range="-0.87 0.35" />
                                    <geom type="mesh" contype="0" conaffinity="0" group="1" rgba="0.4 0.4 0.4 1.0" mesh="Ankle_Cross_Right" />
                                    <body name="right_foot_link" pos="0 -0.00025 -0.012">
                                        <inertial pos="-0.000248 0 -0.00914" quat="0 0.599183 0 0.800612" mass="0.685" diaginertia="0.0027142 0.002385 0.0021708" />
                                        <joint name="Right_Ankle_Roll" pos="0 0 0" axis="1 0 0" limited="true" range="-0.44 0.44" />
                                        <geom type="mesh" contype="0" conaffinity="0" group="1" rgba="0.4 0.4 0.4 1.0" mesh="right_foot_link" />
                                        <geom size="0.1115 0.05 0.015" pos="0.01 0 -0.015" type="box" rgba="0.4 0.4 0.4 0.0" />
                                        <site name="right_foot" pos="0.05 0 -0.025" size="0.01" rgba="0.2 0.8 0.2 0.8" />
                                    </body>
                                </body>
                            </body>
                        </body>
                    </body>
                </body>
            </body>
        </body>
    </worldbody>
    

    
    <include file="include/t1_actuators_full.xml" />
    <include file="include/t1_sensors_common.xml" />
</mujoco>